var caughtError = null;

/**
 * Call a function while guarding against errors that happens within it.
 *
 * @param {String} name of the guard to use for logging or debugging
 * @param {Function} func The function to invoke
 * @param {*} a First argument
 * @param {*} b Second argument
 */
function invokeGuardedCallback(name, func, a) {
  try {
    func(a);
  } catch (x) {
    if (caughtError === null) {
      caughtError = x;
    }
  }
}

var ReactErrorUtils = {
  invokeGuardedCallback,

  /**
   * Invoked by ReactTestUtils.Simulate so that any errors thrown by the event
   * handler are sure to be rethrown by rethrowCaughtError.
   */
  invokeGuardedCallbackWithCatch: invokeGuardedCallback,

  /**
   * During execution of guarded functions we will capture the first error which
   * we will rethrow to be handled by the top level error handler.
   */
  rethrowCaughtError: function() {
    if (caughtError) {
      var error = caughtError;
      caughtError = null;
      throw error;
    }
  }
};

export default ReactErrorUtils;
